<mujoco model="ailamp_scene">
    <include file="robot.xml" />
    <option timestep="0.01"/>

    <visual>
        <headlight diffuse="0.6 0.6 0.6" ambient="0.3 0.3 0.3" specular="0 0 0" />
        <rgba haze="0.15 0.25 0.35 1" />
        <global azimuth="160" elevation="-20" />
    </visual>

    <asset>
        <texture type="skybox" builtin="gradient" rgb1="0.3 0.5 0.7" rgb2="0 0 0" width="512" height="3072" />
        <texture type="2d" name="groundplane" builtin="checker" mark="edge" rgb1="0.2 0.3 0.4" rgb2="0.1 0.2 0.3" markrgb="0.8 0.8 0.8" width="300" height="300" />
        <material name="groundplane" texture="groundplane" texuniform="true" texrepeat="5 5" reflectance="0.2" />
        <material name="target_red" rgba="1 0.12 0.08 1" />
        <material name="ailamp_electronics_dark" rgba="0.05 0.07 0.08 1" />
        <material name="ailamp_pcb_green" rgba="0.02 0.35 0.16 1" />
        <material name="ailamp_camera_black" rgba="0.01 0.01 0.01 1" />
        <material name="ailamp_led_warm" rgba="1.0 0.72 0.32 1" />
    </asset>

    <worldbody>
        <light pos="0 0 3.5" dir="0 0 -1" directional="true" />
        <geom name="floor" size="0 0 0.05" pos="0 0 0" type="plane" material="groundplane" />
        <body name="ailamp_adapter_visuals" pos="0 0 0">
            <geom name="ailamp_jetson_tray_visual" type="box" pos="-0.16 0.08 0.018" size="0.061 0.051 0.006" material="ailamp_electronics_dark" contype="0" conaffinity="0" />
            <geom name="ailamp_electronics_deck_visual" type="box" pos="0.13 0.08 0.024" size="0.0725 0.024 0.005" material="ailamp_pcb_green" contype="0" conaffinity="0" />
            <geom name="ailamp_respeaker_visual" type="box" pos="0.0 0.16 0.035" size="0.0505 0.025 0.0045" material="ailamp_electronics_dark" contype="0" conaffinity="0" />
        </body>
        <body name="ailamp_head_adapter_visuals" pos="0.02 -0.02 0.44">
            <geom name="ailamp_camera_mount_visual" type="box" pos="0.0 -0.03 0.0" size="0.024 0.005 0.021" material="ailamp_camera_black" contype="0" conaffinity="0" />
            <geom name="ailamp_neomatrix_visual" type="box" pos="0.0 -0.036 -0.035" size="0.036 0.002 0.036" material="ailamp_led_warm" contype="0" conaffinity="0" />
        </body>
        <body name="virtual_person_target" pos="0.0 0.0 0.9">
            <joint name="target_slide_x" type="slide" axis="1 0 0" range="-1.2 1.2" />
            <joint name="target_slide_y" type="slide" axis="0 1 0" range="-3.8 -0.35" />
            <geom name="virtual_person_body" type="capsule" fromto="0 0 -0.55 0 0 0.55" size="0.18" material="target_red" contype="0" conaffinity="0" />
            <geom name="virtual_person_head" type="sphere" pos="0 0 0.78" size="0.16" material="target_red" contype="0" conaffinity="0" />
        </body>
        <camera name="ailamp_sim_camera" pos="0 -4.0 1.2" xyaxes="1 0 0 0 0.119 0.993" fovy="55" />
    </worldbody>
</mujoco>
